<?xml version="1.0"?>
<robot xmlns:xacro="http://ros.org/wiki/xacro">

    <xacro:include filename="$(find robinion2s_description)/urdf/balanceboard/robinion2s.structure.head.xacro" />
    <xacro:include filename="$(find robinion2s_description)/urdf/balanceboard/robinion2s.structure.arm.xacro" />
	<xacro:include filename="$(find robinion2s_description)/urdf/robinion2s.transmissions.xacro" />

	<xacro:macro name="robinion2s_r_leg" params="parent">
		
		<joint name="r_leg_base_fixed_joint"
		type="fixed">
			<parent link="${parent}"/>
			<child link="r_foot_link"/>
			<origin xyz="-0.045 -0.155 0.053" rpy="0 0 0"/>
		</joint>

		<!-- Right leg -->
		<link name="r_foot_link">			
			<visual>
				<origin xyz="0.00 0.00 0.00" rpy="0.00 0.00 0.00"/>
				<geometry>
					<mesh filename="package://robinion2s_description/meshes/visual/standard/right_foot_visual.stl"/>
				</geometry>
			</visual>

			<collision>
				<origin xyz="0.045 -0.0145 -0.048" rpy="0.00 0.00 0.00"/>
				<geometry>
					<!-- <mesh filename="package://robinion2s_description/meshes/visual/standard/collision/r_foot_collision.stl"/> -->
					<box size="0.19 0.116 0.01" />
				</geometry>
			</collision>

			<inertial>
				<origin xyz="0.045052 -0.011620 -0.047578" rpy="0.00 0.00 0.00"/>
				<mass value="0.241931"/>
				<inertia ixx="0.000290" ixy="-0.000000" ixz="0.000000"
						 iyy="0.000663" iyz="-0.000010"
						 izz="0.000899" />
			</inertial>
		</link>

		<joint name="r_ankle_roll_joint" type="revolute">
			<parent link="r_foot_link"/>
			<child link="r_ankle_pitch_link"/>
			<origin xyz="0.00 0.00 0.00" rpy="-0.266 0 0"/>
			<axis xyz="-1 0 0"/>
			<limit velocity="4.08" effort="9.90" lower="${-pi*0.5}" upper="${pi*0.5}" />
			<!-- <limit velocity="4.08" effort="100" lower="-3" upper="3" /> -->
			<dynamics damping="0.1" friction="0.0" />
			<implicitSpringDamper>True</implicitSpringDamper>
		</joint>
		<xacro:insert_transmission name="r_ankle_roll_joint" />

		<link name="r_ankle_pitch_link">			
			<visual>
				<origin xyz="0.06575 -0.0245 0.000" rpy="0.00 0.00 0.00"/>
				<geometry>
					<mesh filename="package://robinion2s_description/meshes/visual/standard/right_ankle_roll_pitch_visual.stl"/>
				</geometry>
			</visual>

			<!-- <collision>
				<origin xyz="0.00 0.00 0.00" rpy="0.00 0.00 0.00"/>
				<geometry>
					<mesh filename="package://robinion2s_description/meshes/collision/r_ankle_roll_pitch_collision.stl"/>
				</geometry>
			</collision> -->

			<inertial>
				<origin xyz="-0.020713 0.024167 0.015045" rpy="0.00 0.00 0.00"/>
				<mass value="0.467377"/>
				<inertia ixx="0.000198" ixy="-0.000003" ixz="0.000001"
						 iyy="0.000406" iyz="-0.000000"
						 izz="0.000326" />
			</inertial>
		</link>

		<joint name="r_ankle_pitch_joint" type="revolute">
			<parent link="r_ankle_pitch_link"/>
			<child link="r_knee_pitch_link"/>
			<origin xyz="0.06575 -0.0245 0.00" rpy="0 0 0"/>
			<axis xyz="0 -1 0"/>
			<limit velocity="4.08" effort="9.90" lower="${-pi*0.5}" upper="${pi*0.5}" />
			<!-- <limit velocity="4.08" effort="100" lower="-3" upper="3" /> -->
			<dynamics damping="0.1" friction="0.0" />
			<implicitSpringDamper>True</implicitSpringDamper>
		</joint>
		<xacro:insert_transmission name="r_ankle_pitch_joint" />

		<link name="r_knee_pitch_link">			
			<visual>
				<origin xyz="0.00 0.00 0.19" rpy="0.00 0.00 0.00"/>
				<geometry>
					<mesh filename="package://robinion2s_description/meshes/visual/standard/right_leg_pitch_knee_ankle_visual.stl"/>
				</geometry>
			</visual>

			<!-- <collision>
				<origin xyz="0.00 0.00 0.00" rpy="0.00 0.00 0.00"/>
				<geometry>
					<mesh filename="package://robinion2s_description/meshes/collision/r_hip_yaw_collision.stl"/>
				</geometry>
			</collision> -->
			
			<inertial>
				<origin xyz="0.000420 -0.024965 -0.040918" rpy="0.00 0.00 0.00"/>
				<mass value="0.334780"/>
				<inertia ixx="0.000805" ixy="0.000000" ixz="-0.000012"
						 iyy="0.000752" iyz="-0.000004"
						 izz="0.000120" />
			</inertial>
		</link>

		<joint name="r_knee_pitch_joint" type="revolute">
			<parent link="r_knee_pitch_link"/>
			<child link="r_hip_pitch_link"/>
			<origin xyz="0.000 0.000 0.190" rpy="0 0 0"/>
			<axis xyz="0 -1 0"/>
			<limit velocity="4.08" effort="9.90" lower="${-pi*0.5}" upper="${pi*0.5}" />
			<!-- <limit velocity="4.08" effort="100" lower="-3" upper="3" /> -->
			<dynamics damping="0.1" friction="0.0" />
			<implicitSpringDamper>True</implicitSpringDamper>
		</joint>
		<xacro:insert_transmission name="r_knee_pitch_joint" />

		<link name="r_hip_pitch_link">
			<visual>
				<origin xyz="0.00 0.00 0.19" rpy="0.00 0.00 0.00"/>
				<geometry>
					<mesh filename="package://robinion2s_description/meshes/visual/standard/right_hip_pitch_visual.stl"/>
				</geometry>
			</visual>

			<!-- <collision>
				<origin xyz="0.00 0.00 0.00" rpy="0.00 0.00 0.00"/>
				<geometry>
					<mesh filename="package://robinion2s_description/meshes/collision/r_hip_yaw_collision.stl"/>
				</geometry>
			</collision> -->

			<inertial>
				<origin xyz="0.005543 -0.024500 -0.098751" rpy="0.00 0.00 0.00"/>
				<mass value="0.125336"/>
				<inertia ixx="0.000339" ixy="0.000000" ixz="-0.000026"
						 iyy="0.000300" iyz="0.000000"
						 izz="0.000084" />
			</inertial>
		</link>

		<joint name="r_hip_pitch_joint" type="revolute">
			<parent link="r_hip_pitch_link"/>
			<child link="r_hip_roll_pitch_link"/>
			<origin xyz="0.00 0.00 0.190" rpy="0 0 0"/>
			<axis xyz="0 -1 0"/>
			<limit velocity="4.08" effort="9.90" lower="${-pi*0.5}" upper="${pi*0.5}" />
			<!-- <limit velocity="4.08" effort="100" lower="-3" upper="3" /> -->
			<dynamics damping="0.1" friction="0.0" />
			<implicitSpringDamper>True</implicitSpringDamper>
		</joint>
		<xacro:insert_transmission name="r_hip_pitch_joint" />

		<link name="r_hip_roll_pitch_link">			
			<visual>
				<origin xyz="-0.06575 0.0245 0.000" rpy="0.00 0.00 0.00"/>
				<geometry>
					<mesh filename="package://robinion2s_description/meshes/visual/standard/right_hip_roll_pitch_visual.stl"/>
				</geometry>
			</visual>

			<collision>
				<origin xyz="0.02425 0.0245 0.000" rpy="0.00 0.00 0.00"/>
				<geometry>
					<mesh filename="package://robinion2s_description/meshes/collision/standard/r_hip_roll_pitch_collision.stl"/>
				</geometry>
			</collision>

			<inertial>
				<origin xyz="-0.020713 -0.024167 0.015045" rpy="0.00 0.00 0.00"/>
				<mass value="0.467377"/>
				<inertia ixx="0.000198" ixy="-0.000003" ixz="0.000001"
						 iyy="0.000406" iyz="-0.000000"
						 izz="0.000326" />
			</inertial>
		</link>

		<joint name="r_hip_roll_joint" type="revolute">
			<parent link="r_hip_roll_pitch_link"/>
			<child link="r_hip_yaw_link"/>
			<origin xyz="-0.06575 0.0245 0.000" rpy="0.266 0 0"/>
			<axis xyz="-1 0 0"/>
			<limit velocity="4.08" effort="9.90" lower="${-pi*0.25}" upper="${pi*0.25}" />
			<!-- <limit velocity="4.08" effort="100" lower="-3" upper="3" /> -->
			<dynamics damping="0.1" friction="0.0" />
			<implicitSpringDamper>True</implicitSpringDamper>
		</joint>
		<xacro:insert_transmission name="r_hip_roll_joint" />

		<link name="r_hip_yaw_link">
			<collision>
				<origin xyz="0.042125 0.000 0.050" rpy="0.00 0.00 0.00"/>
				<geometry>
					<mesh filename="package://robinion2s_description/meshes/collision/standard/r_hip_yaw_collision.stl"/>
				</geometry>
			</collision>
			<visual>
				<origin xyz="0.042125 0.000 0.050" rpy="0.00 0.00 0.00"/>
				<geometry>
					<mesh filename="package://robinion2s_description/meshes/visual/standard/r_hip_yaw_visual.stl"/>
				</geometry>
			</visual>
			<inertial>
				<origin xyz="0.002613 0.000000 -0.016031" rpy="0.00 0.00 0.00"/>
				<mass value="0.467377"/>
				<inertia ixx="0.000020" ixy="0.000000" ixz="0.000000"
						 iyy="0.000089" iyz="0.000000"
						 izz="0.000080" />
			</inertial>
		</link>

		<joint name="r_hip_yaw_joint" type="revolute">
			<parent link="r_hip_yaw_link"/>
			<child link="torso_link"/>
			<origin xyz="0.042125 0.000 0.050" rpy="0 0 0"/>
			<axis xyz="0 0 -1"/>
			<limit velocity="3.14" effort="10.6" lower="${-pi*0.9}" upper="${pi*0.9}" />
			<!-- <limit velocity="3.14" effort="1000" lower="-3" upper="3" /> -->
			<dynamics damping="0.1" friction="0.0" />
			<implicitSpringDamper>True</implicitSpringDamper>
		</joint>
		<xacro:insert_transmission name="r_hip_yaw_joint" />

		<link name="torso_link">        
        <visual>
            <origin xyz="0.00 0.055 0.006" rpy="0.00 0.00 0.00"/>
            <geometry>
                <mesh filename="package://robinion2s_description/meshes/visual/standard/lower_body_visual.stl"/>
            </geometry>
        </visual>

		<collision>
            <origin xyz="0.00 0.055 0.006" rpy="0.00 0.00 0.00"/>
            <geometry>
                <mesh filename="package://robinion2s_description/meshes/collision/standard/lower_body_collision.stl"/>
            </geometry>
        </collision>

        <inertial>
            <origin xyz="-0.007122 0.000256 0.034914" rpy="0.00 0.00 0.00"/>
            <mass value="0.960747"/>
            <inertia ixx="0.002662" ixy="0.000002" ixz="0.000113"
                     iyy="0.001197" iyz="0.000003"
                     izz="0.002578" />
        </inertial>
    </link>

	<joint name="l_hip_yaw_joint" type="revolute">
			<parent link="torso_link"/>
			<child link="l_hip_yaw_link"/>
			<origin xyz="0.000 0.11 0.000" rpy="0 0 0"/>
			<axis xyz="0 0 -1"/>
			<limit velocity="3.14" effort="10.6" lower="${-pi*0.9}" upper="${pi*0.9}" />
			<!-- <limit velocity="3.14" effort="100" lower="-3" upper="3" /> -->
			<dynamics damping="0.1" friction="0.0" />
			<implicitSpringDamper>True</implicitSpringDamper>
		</joint>
		<xacro:insert_transmission name="l_hip_yaw_joint" />
	
		<link name="l_hip_yaw_link">
			<visual>
				<origin xyz="0.00 0.00 0.00" rpy="0.00 0.00 0.00"/>
				<geometry>
					<mesh filename="package://robinion2s_description/meshes/visual/standard/l_hip_yaw_visual.stl"/>
				</geometry>
			</visual>

			<collision>
				<origin xyz="0.00 0.00 0.00" rpy="0.00 0.00 0.00"/>
				<geometry>
					<mesh filename="package://robinion2s_description/meshes/collision/standard/l_hip_yaw_collision.stl"/>
				</geometry>
			</collision>

			<inertial>
				<origin xyz="0.002613 0.000000 -0.016031" rpy="0.00 0.00 0.00"/>
				<mass value="0.048671"/>
				<inertia ixx="0.000020" ixy="0.000000" ixz="0.000000"
						 iyy="0.000089" iyz="0.000000"
						 izz="0.000080" />
			</inertial>
		</link>

		<joint name="l_hip_roll_joint" type="revolute">
			<parent link="l_hip_yaw_link"/>
			<child link="l_hip_roll_pitch_link"/>
			<origin xyz="-0.042125 0.000 -0.050" rpy="0.266 0 0"/>
			<axis xyz="-1 0 0"/>
			<limit velocity="4.08" effort="9.90" lower="${-pi*0.266}" upper="${pi*0.25}" />
			<!-- <limit velocity="4.08" effort="100" lower="-3" upper="3" /> -->
			<dynamics damping="0.1" friction="0.0" />
			<implicitSpringDamper>True</implicitSpringDamper>
		</joint>
		<xacro:insert_transmission name="l_hip_roll_joint" />
	
		<link name="l_hip_roll_pitch_link">
			<visual>
				<origin xyz="0.00 0.00 0.00" rpy="0.00 0.00 0.00"/>
				<geometry>
					<mesh filename="package://robinion2s_description/meshes/visual/standard/left_hip_roll_pitch_visual.stl"/>
				</geometry>
			</visual>

			<collision>
				<origin xyz="0.09 0.00 0.00" rpy="0.00 0.00 0.00"/>
				<geometry>
					<mesh filename="package://robinion2s_description/meshes/collision/standard/l_hip_roll_pitch_collision.stl"/>
				</geometry>
			</collision>

			<inertial>
				<origin xyz="0.045037 0.000333 -0.015045" rpy="0.00 0.00 0.00"/>
				<mass value="0.467377"/>
				<inertia ixx="0.000198" ixy="0.000003" ixz="0.000001"
						 iyy="0.000406" iyz="0.000000"
						 izz="0.000326" />
			</inertial>
		</link>	

		<joint name="l_hip_pitch_joint" type="revolute">
			<parent link="l_hip_roll_pitch_link"/>
			<child link="l_hip_pitch_link"/>
			<origin xyz="0.06575 0.0245 0.000" rpy="0 0 0"/>
			<axis xyz="0 -1 0"/>
			<limit velocity="4.08" effort="9.90" lower="${-pi*0.25}" upper="${pi*0.25}" />
			<!-- <limit velocity="4.08" effort="100" lower="-3" upper="3" /> -->
			<dynamics damping="0.1" friction="0.0" />
			<implicitSpringDamper>True</implicitSpringDamper>
		</joint>
		<xacro:insert_transmission name="l_hip_pitch_joint" />
	
		<link name="l_hip_pitch_link">
			<visual>
				<origin xyz="0.00 0.00 0.00" rpy="0.00 0.00 0.00"/>
				<geometry>
					<mesh filename="package://robinion2s_description/meshes/visual/standard/left_hip_pitch_visual.stl"/>
				</geometry>
			</visual>

			<!-- <collision>
				<origin xyz="0.09 0.00 0.00" rpy="0.00 0.00 0.00"/>
				<geometry>
					<mesh filename="package://robinion2s_description/meshes/collision/l_hip_roll_pitch_collision.stl"/>
				</geometry>
			</collision> -->

			<inertial>
				<origin xyz="0.045037 0.000333 -0.015045" rpy="0.00 0.00 0.00"/>
				<mass value="0.467377"/>
				<inertia ixx="0.000198" ixy="0.000003" ixz="0.000001"
						 iyy="0.000406" iyz="0.000000"
						 izz="0.000326" />
			</inertial>
		</link>

		<joint name="l_knee_pitch_joint" type="revolute">
			<parent link="l_hip_pitch_link"/>
			<child link="l_knee_pitch_link"/>
			<origin xyz="0.000 0.000 -0.190" rpy="0 0 0"/>
			<axis xyz="0 -1 0"/>
			<limit velocity="4.08" effort="9.90" lower="${-pi*0.5}" upper="${pi*0.5}" />
			<!-- <limit velocity="4.08" effort="100" lower="-3" upper="3" /> -->
			<dynamics damping="0.1" friction="0.0" />
			<implicitSpringDamper>True</implicitSpringDamper>
		</joint>
		<xacro:insert_transmission name="l_knee_pitch_joint" />

		<link name="l_knee_pitch_link">
			<visual>
				<origin xyz="0.00 0.00 0.00" rpy="0.00 0.00 0.00"/>
				<geometry>
					<mesh filename="package://robinion2s_description/meshes/visual/standard/left_leg_pitch_knee_ankle_visual.stl"/>
				</geometry>
			</visual>

			<!-- <collision>
				<origin xyz="0.00 0.00 0.00" rpy="0.00 0.00 0.00"/>
				<geometry>
					<mesh filename="package://robinion2s_description/meshes/collision/r_hip_yaw_collision.stl"/>
				</geometry>
			</collision> -->
			
			<inertial>
				<origin xyz="0.000420 -0.024035 -0.040918" rpy="0.00 0.00 0.00"/>
				<mass value="0.334780"/>
				<inertia ixx="0.000805" ixy="0.000000" ixz="-0.000012"
						 iyy="0.000752" iyz="-0.000004"
						 izz="0.000120" />
			</inertial>
		</link>

		<joint name="l_ankle_pitch_joint" type="revolute">
			<parent link="l_knee_pitch_link"/>
			<child link="l_ankle_pitch_link"/>
			<origin xyz="0.000 0.000 -0.190" rpy="0 0 0"/>
			<axis xyz="0 -1 0"/>
			<limit velocity="4.08" effort="9.90" lower="${-pi*0.5}" upper="${pi*0.5}" />
			<!-- <limit velocity="4.08" effort="100" lower="-3" upper="3" /> -->
			<dynamics damping="0.1" friction="0.0" />
			<implicitSpringDamper>True</implicitSpringDamper>
		</joint>
		<xacro:insert_transmission name="l_ankle_pitch_joint" />

		<link name="l_ankle_pitch_link">
			<visual>
				<origin xyz="0.00 0.00 0.00" rpy="0.00 0.00 0.00"/>
				<geometry>
					<mesh filename="package://robinion2s_description/meshes/visual/standard/left_ankle_roll_pitch_visual.stl"/>
				</geometry>
			</visual>

			<!-- <collision>
				<origin xyz="0.00 0.00 0.00" rpy="0.00 0.00 0.00"/>
				<geometry>
					<mesh filename="package://robinion2s_description/meshes/collision/l_ankle_roll_pitch_collision.stl"/>
				</geometry>
			</collision> -->

			<inertial>
				<origin xyz="-0.020713 -0.024167 0.015045" rpy="0.00 0.00 0.00"/>
				<mass value="0.467377"/>
				<inertia ixx="0.000198" ixy="-0.000003" ixz="0.000001"
						 iyy="0.000406" iyz="-0.000000"
						 izz="0.000326" />
			</inertial>
		</link>

		<joint name="l_ankle_roll_joint" type="revolute">
			<parent link="l_ankle_pitch_link"/>
			<child link="l_foot_link"/>
			<origin xyz="-0.06575 -0.0245 0.000" rpy="-0.266 0 0"/>
			<axis xyz="-1 0 0"/>
			<limit velocity="4.08" effort="9.90" lower="${-pi*0.5}" upper="${pi*0.5}" />
			<!-- <limit velocity="4.08" effort="100" lower="-3" upper="3" /> -->
			<dynamics damping="0.1" friction="0.0" />
			<implicitSpringDamper>True</implicitSpringDamper>
		</joint>
		<xacro:insert_transmission name="l_ankle_roll_joint" />

		<link name="l_foot_link">			
			<visual>
				<origin xyz="0.00 0.00 0.00" rpy="0.00 0.00 0.00"/>
				<geometry>
					<mesh filename="package://robinion2s_description/meshes/visual/standard/left_foot_visual.stl"/>
				</geometry>
			</visual>

			<collision>
				<origin xyz="0.045 0.0145 -0.048" rpy="0.00 0.00 0.00"/>
				<geometry>
					<!-- <mesh filename="package://robinion2s_description/meshes/collision/l_foot_collision.stl"/> -->
					<box size="0.19 0.116 0.01" />
				</geometry>
			</collision>

			<inertial>
				<origin xyz="0.045052 0.011620 -0.047578" rpy="0.00 0.00 0.00"/>
				<mass value="0.241931"/>
				<inertia ixx="0.000290" ixy="-0.000000" ixz="0.000000"
						 iyy="0.000663" iyz="-0.000010"
						 izz="0.000899" />
			</inertial>
		</link>

		<joint name="torso_pitch_joint" type="revolute">
			<parent link="torso_link"/>
			<child link="upper_body_link"/>
			<origin xyz="0.019 0.0795 0.07675" rpy="0 0 0"/>
			<axis xyz="0 1 0"/>
			<limit velocity="3.14" effort="10.6" lower="-0.52" upper="${pi*0.5}" />
			<!-- <limit velocity="3.14" effort="100" lower="-3" upper="3" /> -->
			<dynamics damping="0.1" friction="0.0" />
			<implicitSpringDamper>True</implicitSpringDamper>
		</joint>
		<xacro:insert_transmission name="torso_pitch_joint" />

		<link name="upper_body_link">
			<collision>
				<origin xyz="0.00 0.00 0.00" rpy="0.00 0.00 0.00"/>
				<geometry>
					<mesh filename="package://robinion2s_description/meshes/collision/standard/upper_body_collision.stl"/>
				</geometry>
			</collision>
			<visual>
				<origin xyz="0.00 0.00 0.00" rpy="0.00 0.00 0.00"/>
				<geometry>
					<mesh filename="package://robinion2s_description/meshes/visual/standard/upper_body_visual.stl"/>
				</geometry>
			</visual>
			<inertial>
				<origin xyz="-0.029870 -0.024411 0.123492" rpy="0.00 0.00 0.00"/>
				<mass value="1.234139"/>
				<inertia ixx="0.006795" ixy="0.000000" ixz="-0.000098"
						iyy="0.003101" iyz="-0.000005"
						izz="0.006100" />
			</inertial>
		</link>

		<joint name="imu_fixed_joint" type="fixed">
			<parent link="upper_body_link"/>
			<child link="imu_link"/>
			<origin xyz="-0.021 -0.025 0.122" rpy="0 0 0"/>
		</joint>

		<link name="imu_link">
		</link>

	</xacro:macro>

    <xacro:robinion_head parent="upper_body_link" />
    <xacro:robinion_l_arm parent="upper_body_link" />
    <xacro:robinion_r_arm parent="upper_body_link" />

</robot>
